{"name": "test_get_login_submit", "status": "failed", "statusDetails": {"message": "AssertionError: assert '2' == '0'\n  - 2\n  + 0", "trace": "self = <tests.test_testcase.TestSingle object at 0x10b9c90f0>\n\n    @allure.story(\"测试3\")\n    def test_get_login_submit(self):\n        \"\"\" 呵呵呵呵1234\"\"\"\n        single_testcase_yaml = os.path.join(os.path.dirname(__file__), \"api\", \"get_login_submit.yml\")\n    \n        result = self.run.run_yml(single_testcase_yaml)\n        logger.info(\"666666666\"+str(result))\n        for ass in result[0]:\n            logger.info(ass[\"url\"])\n            logger.info(\"\\033[1;31m=======Assert=====\\033[0m\")\n            logger.info(\"\\033[1;36mexpected:\\033[0m\" + '\\n\\t' + \"{}={}\".format(\"expected\", ass[\"expected\"]))\n            logger.info(\"\\033[1;32mactual:\\033[0m\" + '\\n\\t' + \"{}={}\".format(\"actual\", ass[\"actual\"]))\n            try:\n>               assert ass[\"expected\"] == ass[\"actual\"]\nE               AssertionError: assert '2' == '0'\nE                 - 2\nE                 + 0\n\ntest_testcase.py:74: AssertionError\n\nDuring handling of the above exception, another exception occurred:\n\nself = <tests.test_testcase.TestSingle object at 0x10b9c90f0>\n\n    @allure.story(\"测试3\")\n    def test_get_login_submit(self):\n        \"\"\" 呵呵呵呵1234\"\"\"\n        single_testcase_yaml = os.path.join(os.path.dirname(__file__), \"api\", \"get_login_submit.yml\")\n    \n        result = self.run.run_yml(single_testcase_yaml)\n        logger.info(\"666666666\"+str(result))\n        for ass in result[0]:\n            logger.info(ass[\"url\"])\n            logger.info(\"\\033[1;31m=======Assert=====\\033[0m\")\n            logger.info(\"\\033[1;36mexpected:\\033[0m\" + '\\n\\t' + \"{}={}\".format(\"expected\", ass[\"expected\"]))\n            logger.info(\"\\033[1;32mactual:\\033[0m\" + '\\n\\t' + \"{}={}\".format(\"actual\", ass[\"actual\"]))\n            try:\n                assert ass[\"expected\"] == ass[\"actual\"]\n            except AssertionError:\n>               assert ass[\"expected\"] == ass[\"actual\"]\nE               AssertionError: assert '2' == '0'\nE                 - 2\nE                 + 0\n\ntest_testcase.py:76: AssertionError"}, "description": " 呵呵呵呵1234", "attachments": [{"name": "log", "source": "f5e3a0ca-ea8a-4e57-af97-22fc1ada4aa7-attachment.txt", "type": "text/plain"}, {"name": "stdout", "source": "47e04a9a-b7de-45a2-99f2-ee13678e0323-attachment.txt", "type": "text/plain"}, {"name": "stderr", "source": "f0689891-88d3-48e9-a051-fc3b9f5a1e2b-attachment.txt", "type": "text/plain"}], "start": 1576600899218, "stop": 1576600899582, "uuid": "e35bec6c-0930-4ac2-89b6-8917b718d0cb", "historyId": "9d45b30fd97667aff13f3a162735a3a9", "fullName": "test_testcase.TestSingle#test_get_login_submit", "labels": [{"name": "story", "value": "测试3"}, {"name": "feature", "value": "测试接口"}, {"name": "suite", "value": "test_testcase"}, {"name": "subSuite", "value": "TestSingle"}, {"name": "host", "value": "anxiaodongdeMacBook-Pro.local"}, {"name": "thread", "value": "5992-MainThread"}, {"name": "framework", "value": "pytest"}, {"name": "language", "value": "cpython3"}, {"name": "package", "value": "test_testcase"}]}