{"name": "test_get_login_submit", "status": "failed", "statusDetails": {"message": "AssertionError: assert '2' == '0'\n  - 2\n  + 0", "trace": "self = <tests.test_testcase.TestSingle object at 0x105717a90>\n\n    @allure.story(\"测试3\")\n    def test_get_login_submit(self):\n        \"\"\" 呵呵呵呵1234\"\"\"\n        single_testcase_yaml = os.path.join(os.path.dirname(__file__), \"api\", \"get_login_submit.yml\")\n    \n        result = self.run.run_yml(single_testcase_yaml)\n        logger.info(\"666666666\"+str(result))\n        for ass in result[0]:\n            logger.info(\"hehjehehehhhjhjhjhejhjehjehje\")\n            logger.info(ass[\"url\"])\n            logger.info(\"=======Assert=====\")\n            logger.info(\"expected:{}\".format( ass[\"expected\"]))\n            logger.info(\"actual:{}\".format(ass[\"actual\"]))\n            try:\n>               assert ass[\"expected\"] == ass[\"actual\"]\nE               AssertionError: assert '2' == '0'\nE                 - 2\nE                 + 0\n\ntest_testcase.py:75: AssertionError\n\nDuring handling of the above exception, another exception occurred:\n\nself = <tests.test_testcase.TestSingle object at 0x105717a90>\n\n    @allure.story(\"测试3\")\n    def test_get_login_submit(self):\n        \"\"\" 呵呵呵呵1234\"\"\"\n        single_testcase_yaml = os.path.join(os.path.dirname(__file__), \"api\", \"get_login_submit.yml\")\n    \n        result = self.run.run_yml(single_testcase_yaml)\n        logger.info(\"666666666\"+str(result))\n        for ass in result[0]:\n            logger.info(\"hehjehehehhhjhjhjhejhjehjehje\")\n            logger.info(ass[\"url\"])\n            logger.info(\"=======Assert=====\")\n            logger.info(\"expected:{}\".format( ass[\"expected\"]))\n            logger.info(\"actual:{}\".format(ass[\"actual\"]))\n            try:\n                assert ass[\"expected\"] == ass[\"actual\"]\n            except AssertionError:\n>               assert ass[\"expected\"] == ass[\"actual\"]\nE               AssertionError: assert '2' == '0'\nE                 - 2\nE                 + 0\n\ntest_testcase.py:77: AssertionError"}, "description": " 呵呵呵呵1234", "attachments": [{"name": "log", "source": "11666fdc-3a23-4a88-9d33-098b914105a6-attachment.txt", "type": "text/plain"}, {"name": "stdout", "source": "5a65a8b9-82aa-449d-9ad7-5de278b1b62b-attachment.txt", "type": "text/plain"}, {"name": "stderr", "source": "e6c2f50a-964a-44ad-8c77-46ef0d2b6baf-attachment.txt", "type": "text/plain"}], "start": 1576602519261, "stop": 1576602519626, "uuid": "cf7c2f87-3bcb-4195-8b23-ae94e6139bdb", "historyId": "9d45b30fd97667aff13f3a162735a3a9", "fullName": "test_testcase.TestSingle#test_get_login_submit", "labels": [{"name": "feature", "value": "测试接口"}, {"name": "story", "value": "测试3"}, {"name": "suite", "value": "test_testcase"}, {"name": "subSuite", "value": "TestSingle"}, {"name": "host", "value": "anxiaodongdeMacBook-Pro.local"}, {"name": "thread", "value": "7637-MainThread"}, {"name": "framework", "value": "pytest"}, {"name": "language", "value": "cpython3"}, {"name": "package", "value": "test_testcase"}]}