{"name": "test_get_login_submit", "status": "failed", "statusDetails": {"message": "AssertionError: assert '2' == '0'\n  - 2\n  + 0", "trace": "self = <tests.test_testcase.TestSingle object at 0x10989ef60>\n\n    @allure.story(\"测试3\")\n    def test_get_login_submit(self):\n        \"\"\" 呵呵呵呵1234\"\"\"\n        single_testcase_yaml = os.path.join(os.path.dirname(__file__), \"api\", \"get_login_submit.yml\")\n    \n        result = self.run.run_yml(single_testcase_yaml)\n        print(\"666666666\"+str(result))\n        for ass in result[0]:\n            print(ass[\"url\"])\n            print(\"\\033[1;31m=======Assert=====\\033[0m\")\n            print(\"\\033[1;36mexpected:\\033[0m\" + '\\n\\t' + \"{}={}\".format(\"expected\", ass[\"expected\"]))\n            print(\"\\033[1;32mactual:\\033[0m\" + '\\n\\t' + \"{}={}\".format(\"actual\", ass[\"actual\"]))\n            try:\n>               assert ass[\"expected\"] == ass[\"actual\"]\nE               AssertionError: assert '2' == '0'\nE                 - 2\nE                 + 0\n\ntest_testcase.py:72: AssertionError\n\nDuring handling of the above exception, another exception occurred:\n\nself = <tests.test_testcase.TestSingle object at 0x10989ef60>\n\n    @allure.story(\"测试3\")\n    def test_get_login_submit(self):\n        \"\"\" 呵呵呵呵1234\"\"\"\n        single_testcase_yaml = os.path.join(os.path.dirname(__file__), \"api\", \"get_login_submit.yml\")\n    \n        result = self.run.run_yml(single_testcase_yaml)\n        print(\"666666666\"+str(result))\n        for ass in result[0]:\n            print(ass[\"url\"])\n            print(\"\\033[1;31m=======Assert=====\\033[0m\")\n            print(\"\\033[1;36mexpected:\\033[0m\" + '\\n\\t' + \"{}={}\".format(\"expected\", ass[\"expected\"]))\n            print(\"\\033[1;32mactual:\\033[0m\" + '\\n\\t' + \"{}={}\".format(\"actual\", ass[\"actual\"]))\n            try:\n                assert ass[\"expected\"] == ass[\"actual\"]\n            except AssertionError:\n>               assert ass[\"expected\"] == ass[\"actual\"]\nE               AssertionError: assert '2' == '0'\nE                 - 2\nE                 + 0\n\ntest_testcase.py:74: AssertionError"}, "description": " 呵呵呵呵1234", "attachments": [{"name": "log", "source": "4d95d984-df85-4ffa-94b3-5ea77f0e43b6-attachment.txt", "type": "text/plain"}, {"name": "stdout", "source": "923fd122-ce72-420f-b69f-6c7264a0a1be-attachment.txt", "type": "text/plain"}, {"name": "stderr", "source": "80861b4c-cd4b-4008-8c23-2924907ba05c-attachment.txt", "type": "text/plain"}], "start": 1576600512825, "stop": 1576600513193, "uuid": "1c3985da-c6d0-4e7a-9249-ba8c3eaaed09", "historyId": "9d45b30fd97667aff13f3a162735a3a9", "fullName": "test_testcase.TestSingle#test_get_login_submit", "labels": [{"name": "feature", "value": "测试接口"}, {"name": "story", "value": "测试3"}, {"name": "suite", "value": "test_testcase"}, {"name": "subSuite", "value": "TestSingle"}, {"name": "host", "value": "anxiaodongdeMacBook-Pro.local"}, {"name": "thread", "value": "5794-MainThread"}, {"name": "framework", "value": "pytest"}, {"name": "language", "value": "cpython3"}, {"name": "package", "value": "test_testcase"}]}